Workbook
Name DVCategory: Calc!$F$12:$F$17
Name DVCur: Calc!$I$12:$I$13
Name DVGrowth: Calc!$A$162:$U$162
Name DVLine: Calc!$J$12:$J$13
Name DVMonth: Calc!$D$12:$D$24
Name DVProduct: Calc!$H$12:$H$37
Name DVQuarter: Calc!$C$12:$C$16
Name DVRegion: Calc!$E$12:$E$17
Name DVSales: Calc!$G$12:$G$18
Name DVYear: Calc!$B$12:$B$16

Sheet Dashboard
A1: SALES ANALYTICS DASHBOARD 2022-2025 | Interactive Sales Performance | AB1: HELPERS
A2: YEAR | C2: QUARTER | E2: MONTH | G2: REGION | I2: CATEGORY | K2: SALESPERSON | M2: PRODUCT | P2: GROWTH % | Q2: CURRENCY | S2: TARGET | AB2: =IF(Q3="USD",1/18.5,1) -> 1 | AC2: =SUM(Calc!$B$42:$B$53)*(1+AB3/100)*AB2 -> 7862714.1 | AD2: Jan
A3: 2024 | C3: All | E3: All | G3: All | I3: All | K3: All | M3: All | P3: 60 | Q3: EGP | S3: ON | AB3: =P3 -> 60 | AC3: =IF(AB4=1,AC$2,"") -> 7862714.1 | AD3: Feb
A4: ="ACTIVE FILTERS YEAR = "&A3&" | QUARTER = "&C3&" | MONTH = "&E3&" | REGION = "&G3&" | CATEGORY = "&I3&" | SALESPERSON = "&K3&" | PRODUCT = "&M3&" | GROWTH = "&P3&"% | CURRENCY = "&Q3&" | TARGET = "&S3 -> ACTIVE FILTERS YEAR = 2024 | QUARTER = All | MONTH = All | REGION = All | CATEGORY = All | SALESPERSON = All | PRODUCT = All | GROWTH = 60% | CURRENCY = EGP | TARGET = ON | AB4: =IF(S3="ON",1,0) -> 1 | AC4: =IF(AB4=1,AC$2,"") -> 7862714.1 | AD4: Mar
A5: =IF(Q3="USD","TOTAL REVENUE (USD)","TOTAL REVENUE (EGP)") -> TOTAL REVENUE (EGP) | C5: ="TOTAL ORDERS" -> TOTAL ORDERS | E5: ="TOTAL UNITS" -> TOTAL UNITS | G5: =IF(Q3="USD","AVG ORDER VALUE (USD)","AVG ORDER VALUE (EGP)") -> AVG ORDER VALUE (EGP) | I5: =IF(Q3="USD","TOTAL PROFIT (USD)","TOTAL PROFIT (EGP)") -> TOTAL PROFIT (EGP) | K5: ="PROFIT MARGIN" -> PROFIT MARGIN | M5: =TEXT(NOW(),"HH:MM:SS")&" UPDATED" -> 04:47:34 UPDATED | Q5: GO TO CALC 👨‍🦯 | AC5: =IF(AB4=1,AC$2,"") -> 7862714.1 | AD5: Apr
A6: =SUM(Calc!$B$42:$B$53)*$AB$2 -> 4914196.3 | C6: =SUM(Calc!$C$42:$C$53) -> 180 | E6: =SUM(Calc!$D$42:$D$53) -> 3831 | G6: =IFERROR(SUM(Calc!$B$42:$B$53)/SUM(Calc!$C$42:$C$53),0)*$AB$2 -> 27301.091 | I6: =SUM(Calc!$F$42:$F$53)*$AB$2 -> 1867394.6 | K6: =IFERROR(SUM(Calc!$F$42:$F$53)/SUM(Calc!$B$42:$B$53),0) -> 0.38 | AC6: =IF(AB4=1,AC$2,"") -> 7862714.1 | AD6: May
A7: =IF(Q3="USD","TOTAL COST (USD)","TOTAL COST (EGP)") -> TOTAL COST (EGP) | C7: BEST MONTH | E7: AVG PROFIT / ORDER | G7: YOY GROWTH % | I7: COST RATIO % | K7: PEAK MONTH REVENUE | AC7: =IF(AB4=1,AC$2,"") -> 7862714.1 | AD7: Jun
A8: =SUM(Calc!$E$42:$E$53)*$AB$2 -> 3046801.7 | C8: =INDEX(Dashboard!$AD$2:$AD$13,MATCH(MAX(Calc!$I$42:$I$53),Calc!$I$42:$I$53,0)) -> Dec | E8: =IFERROR(SUM(Calc!$F$42:$F$53)/SUM(Calc!$C$42:$C$53),0)*$AB$2 -> 10374.415 | G8: =Calc!$F$166 -> 0.48732721 | I8: =IFERROR(SUM(Calc!$E$42:$E$53)/SUM(Calc!$B$42:$B$53),0) -> 0.62 | K8: =MAX(Calc!$I$42:$I$53) -> 931831.95 | AC8: =IF(AB4=1,AC$2,"") -> 7862714.1 | AD8: Jul
AC9: =IF(AB4=1,AC$2,"") -> 7862714.1 | AD9: Aug
A10: BEST CATEGORY | D10: TOP SALESPERSON | G10: PROJECTED REVENUE | P10: GoTo Data 👨‍🦯 | AC10: =IF(AB4=1,AC$2,"") -> 7862714.1 | AD10: Sep
A11: =INDEX(Calc!$A$75:$A$79,MATCH(MAX(Calc!$B$75:$B$79),Calc!$B$75:$B$79,0)) -> Electronics | D11: =INDEX(Calc!$A$84:$A$89,MATCH(MAX(Calc!$B$84:$B$89),Calc!$B$84:$B$89,0)) -> Mona Adel | G11: =(SUM(Calc!$B$42:$B$53))*(1+$P$3/100)*$AB$2 -> 7862714.1 | AC11: =IF(AB4=1,AC$2,"") -> 7862714.1 | AD11: Oct
AC12: =IF(AB4=1,AC$2,"") -> 7862714.1 | AD12: Nov
AC13: =IF(AB4=1,AC$2,"") -> 7862714.1 | AD13: Dec
AC14: =IF(AB4=1,AC$2,"") -> 7862714.1

Sheet Data
A1: Date | B1: Year | C1: Quarter | D1: MonthNum | E1: Month | F1: Region | G1: Category | H1: Product | I1: Salesperson | J1: Units | K1: Unit Price | L1: Revenue | M1: Cost | N1: Profit
A2: 44568.417 | B2: 2022 | C2: Q1 | D2: 1 | E2: Jan | F2: East | G2: Electronics | H2: Tablet | I2: Nour Ibrahim | J2: 29 | K2: 2127.12 | L2: 61686.48 | M2: 38245.62 | N2: 23440.86
A3: 44938.417 | B3: 2023 | C3: Q1 | D3: 1 | E3: Jan | F3: North | G3: Clothing | H3: Jacket | I3: Omar Mostafa | J3: 20 | K3: 417.14 | L3: 8342.8 | M3: 5172.54 | N3: 3170.26
A4: 45318.417 | B4: 2024 | C4: Q1 | D4: 1 | E4: Jan | F4: West | G4: Grocery | H4: Coffee | I4: Ahmed Hassan | J4: 52 | K4: 131.34 | L4: 6829.68 | M4: 4234.4 | N4: 2595.28
A5: 45659.417 | B5: 2025 | C5: Q1 | D5: 1 | E5: Jan | F5: Central | G5: Clothing | H5: Sneakers | I5: Ahmed Hassan | J5: 10 | K5: 181.21 | L5: 1812.1 | M5: 1123.5 | N5: 688.6
A6: 44595.417 | B6: 2022 | C6: Q1 | D6: 2 | E6: Feb | F6: Central | G6: Furniture | H6: Desk | I6: Khaled Youssef | J6: 5 | K6: 1320.3 | L6: 6601.5 | M6: 4092.93 | N6: 2508.57
A7: 44985.417 | B7: 2023 | C7: Q1 | D7: 2 | E7: Feb | F7: North | G7: Grocery | H7: Tea | I7: Ahmed Hassan | J7: 1 | K7: 74.41 | L7: 74.41 | M7: 46.13 | N7: 28.28
A8: 45330.417 | B8: 2024 | C8: Q1 | D8: 2 | E8: Feb | F8: North | G8: Grocery | H8: Sugar | I8: Mona Adel | J8: 14 | K8: 106.46 | L8: 1490.44 | M8: 924.07 | N8: 566.37
A9: 45696.417 | B9: 2025 | C9: Q1 | D9: 2 | E9: Feb | F9: Central | G9: Sports | H9: Dumbbell Set | I9: Khaled Youssef | J9: 17 | K9: 333.49 | L9: 5669.33 | M9: 3514.98 | N9: 2154.35
A10: 44634.417 | B10: 2022 | C10: Q1 | D10: 3 | E10: Mar | F10: East | G10: Furniture | H10: Bookshelf | I10: Ahmed Hassan | J10: 9 | K10: 1612.3 | L10: 14510.7 | M10: 8996.63 | N10: 5514.07
A11: 45002.417 | B11: 2023 | C11: Q1 | D11: 3 | E11: Mar | F11: East | G11: Sports | H11: Yoga Mat | I11: Mona Adel | J11: 22 | K11: 384.75 | L11: 8464.5 | M11: 5247.99 | N11: 3216.51
A12: 45360.417 | B12: 2024 | C12: Q1 | D12: 3 | E12: Mar | F12: East | G12: Grocery | H12: Sugar | I12: Mona Adel | J12: 9 | K12: 79.3 | L12: 713.7 | M12: 442.49 | N12: 271.21
A13: 45736.417 | B13: 2025 | C13: Q1 | D13: 3 | E13: Mar | F13: West | G13: Furniture | H13: Sofa | I13: Omar Mostafa | J13: 24 | K13: 1329.6 | L13: 31910.4 | M13: 19784.45 | N13: 12125.95
... A721: 45994.417 | B721: 2025 | C721: Q4 | D721: 12 | E721: Dec | F721: South | G721: Clothing | H721: T-Shirt | I721: Khaled Youssef | J721: 24 | K721: 168.55 | L721: 4045.2 | M721: 2508.02 | N721: 1537.18

Sheet Calc
A1: CALC ENGINE - DYNAMIC FORMULA LAYER
A2: Read-only formula layer driving the Dashboard. v2: quarter/month/product filters, year + product + top-10 + region x category matrix + KPI helpers.
A4: 1 | CURRENT SELECTIONS (read from the Dashboard controls) | L4: Go To
A5: FIELD | B5: YEAR | C5: QUARTER | D5: MONTH | E5: REGION | F5: CATEGORY | G5: SALESPERSON | H5: PRODUCT | I5: GROWTH % | J5: CURRENCY | K5: TARGET | L5: Dashboard 👨‍🦯
A6: ENGINE | B6: =Dashboard!A3 -> 2024 | C6: =Dashboard!C3 -> All | D6: =Dashboard!E3 -> All | E6: =Dashboard!G3 -> All | F6: =Dashboard!I3 -> All | G6: =Dashboard!K3 -> All | H6: =Dashboard!M3 -> All | I6: =Dashboard!P3 -> 60 | J6: =Dashboard!Q3 -> EGP | K6: =Dashboard!S3 -> ON
A7: READABLE | B7: =B6 -> 2024 | C7: =C6 -> All | D7: =D6 -> All | E7: =E6 -> All | F7: =F6 -> All | G7: =G6 -> All | H7: =H6 -> All | I7: =I6 -> 60 | ... K7: =K6 -> ON | L7: GoTo Data 👨‍🦯
A10: 2 | DROPDOWN LIST SOURCES - feed the in-cell dropdowns on the Dashboard
B11: YEAR | C11: QUARTER | D11: MONTH | E11: REGION | F11: CATEGORY | G11: SALESPERSON | H11: PRODUCT | I11: CURRENCY | J11: TARGET
B12: All | C12: All | D12: All | E12: All | F12: All | G12: All | H12: All | I12: EGP | J12: ON
B13: 2022 | C13: Q1 | D13: Jan | E13: North | F13: Grocery | G13: Ahmed Hassan | H13: Bookshelf | I13: USD | J13: OFF
B14: 2023 | C14: Q2 | D14: Feb | E14: South | F14: Furniture | G14: Sara Ali | H14: Coffee
B15: 2024 | C15: Q3 | D15: Mar | E15: East | F15: Clothing | G15: Omar Mostafa | H15: Cooking Oil
B16: 2025 | C16: Q4 | D16: Apr | E16: West | F16: Sports | G16: Nour Ibrahim | H16: Desk
D17: May | E17: Central | F17: Electronics | G17: Khaled Youssef | H17: Dumbbell Set
D18: Jun | G18: Mona Adel | H18: Floor Lamp
D19: Jul | H19: Football
D20: Aug | H20: Headset
D21: Sep | H21: Jacket
D22: Oct | H22: Jeans
D23: Nov | H23: Laptop
D24: Dec | H24: Monitor
H25: Office Chair
H26: Rice
H27: Smartphone
H28: Sneakers
H29: Sofa
H30: Sugar
H31: Sweater
H32: T-Shirt
H33: Tablet
H34: Tea
H35: Tennis Racket
H36: Training Jersey
H37: Yoga Mat
A40: 3 | MONTHLY TOTALS (Revenue / Orders / Units / Cost / Profit)
A41: Month | B41: Revenue | C41: Orders | D41: Units | E41: Cost | F41: Profit | G41: SHARE % | H41: YoY % | I41: Revenue USD | J41: Profit USD
A42: 1 | B42: =SUMPRODUCT((SalesData[MonthNum]=$A$42)*(($B$6="All")+(SalesData[Year]=$B$6))*(($C$6="All")+(SalesData[Quarter]=$C$6))*(($E$6="All")+(SalesData[Region]=$E$6))*(($F$6="All")+(SalesData[Category]=$F$6))*(($G$6="All")+(SalesData[Salesperson]=$G$6))*(($H$6="All")+(SalesData[Product]=$H$6))*SalesData[Revenue]) -> 798620.35 | C42: =SUMPRODUCT((SalesData[MonthNum]=$A$42)*(($B$6="All")+(SalesData[Year]=$B$6))*(($C$6="All")+(SalesData[Quarter]=$C$6))*(($E$6="All")+(SalesData[Region]=$E$6))*(($F$6="All")+(SalesData[Category]=$F$6))*(($G$6="All")+(SalesData[Salesperson]=$G$6))*(($H$6="All")+(SalesData[Product]=$H$6))*((SalesData[Units]<>0))) -> 15 | D42: =SUMPRODUCT((SalesData[MonthNum]=$A$42)*(($B$6="All")+(SalesData[Year]=$B$6))*(($C$6="All")+(SalesData[Quarter]=$C$6))*(($E$6="All")+(SalesData[Region]=$E$6))*(($F$6="All")+(SalesData[Category]=$F$6))*(($G$6="All")+(SalesData[Salesperson]=$G$6))*(($H$6="All")+(SalesData[Product]=$H$6))*SalesData[Units]) -> 463 | E42: =SUMPRODUCT((SalesData[MonthNum]=$A$42)*(($B$6="All")+(SalesData[Year]=$B$6))*(($C$6="All")+(SalesData[Quarter]=$C$6))*(($E$6="All")+(SalesData[Region]=$E$6))*(($F$6="All")+(SalesData[Category]=$F$6))*(($G$6="All")+(SalesData[Salesperson]=$G$6))*(($H$6="All")+(SalesData[Product]=$H$6))*SalesData[Cost]) -> 495144.61 | F42: =SUMPRODUCT((SalesData[MonthNum]=$A$42)*(($B$6="All")+(SalesData[Year]=$B$6))*(($C$6="All")+(SalesData[Quarter]=$C$6))*(($E$6="All")+(SalesData[Region]=$E$6))*(($F$6="All")+(SalesData[Category]=$F$6))*(($G$6="All")+(SalesData[Salesperson]=$G$6))*(($H$6="All")+(SalesData[Product]=$H$6))*SalesData[Profit]) -> 303475.74 | G42: =IFERROR(B42/SUM($B$42:$B$53),0) -> 0.16251291 | H42: =IF(NOT(ISNUMBER($B$6)),"n/a",IF($B$6<=2022,"n/a",IFERROR((B42-SUMPRODUCT((SalesData[MonthNum]=$A$42)*(SalesData[Year]=$B$6-1)*(($C$6="All")+(SalesData[Quarter]=$C$6))*(($D$6="All")+(SalesData[Month]=$D$6))*(($E$6="All")+(SalesData[Region]=$E$6))*(($F$6="All")+(SalesData[Category]=$F$6))*(($G$6="All")+(SalesData[Salesperson]=$G$6))*(($H$6="All")+(SalesData[Product]=$H$6))*SalesData[Revenue]))/SUMPRODUCT((SalesData[MonthNum]=$A$42)*(SalesData[Year]=$B$6-1)*(($C$6="All")+(SalesData[Quarter]=$C$6))*(($D$6="All")+(SalesData[Month]=$D$6))*(($E$6="All")+(SalesData[Region]=$E$6))*(($F$6="All")+(SalesData[Category]=$F$6))*(($G$6="All")+(SalesData[Salesperson]=$G$6))*(($H$6="All")+(SalesData[Product]=$H$6))*SalesData[Revenue]),"n/a"))) -> 0.58285342 | I42: =B42*Dashboard!$AB$2 -> 798620.35 | J42: =F42*Dashboard!$AB$2 -> 303475.74
A43: 2 | B43: =SUMPRODUCT((SalesData[MonthNum]=$A$43)*(($B$6="All")+(SalesData[Year]=$B$6))*(($C$6="All")+(SalesData[Quarter]=$C$6))*(($E$6="All")+(SalesData[Region]=$E$6))*(($F$6="All")+(SalesData[Category]=$F$6))*(($G$6="All")+(SalesData[Salesperson]=$G$6))*(($H$6="All")+(SalesData[Product]=$H$6))*SalesData[Revenue]) -> 384847.49 | C43: =SUMPRODUCT((SalesData[MonthNum]=$A$43)*(($B$6="All")+(SalesData[Year]=$B$6))*(($C$6="All")+(SalesData[Quarter]=$C$6))*(($E$6="All")+(SalesData[Region]=$E$6))*(($F$6="All")+(SalesData[Category]=$F$6))*(($G$6="All")+(SalesData[Salesperson]=$G$6))*(($H$6="All")+(SalesData[Product]=$H$6))*((SalesData[Units]<>0))) -> 15 | D43: =SUMPRODUCT((SalesData[MonthNum]=$A$43)*(($B$6="All")+(SalesData[Year]=$B$6))*(($C$6="All")+(SalesData[Quarter]=$C$6))*(($E$6="All")+(SalesData[Region]=$E$6))*(($F$6="All")+(SalesData[Category]=$F$6))*(($G$6="All")+(SalesData[Salesperson]=$G$6))*(($H$6="All")+(SalesData[Product]=$H$6))*SalesData[Units]) -> 197 | E43: =SUMPRODUCT((SalesData[MonthNum]=$A$43)*(($B$6="All")+(SalesData[Year]=$B$6))*(($C$6="All")+(SalesData[Quarter]=$C$6))*(($E$6="All")+(SalesData[Region]=$E$6))*(($F$6="All")+(SalesData[Category]=$F$6))*(($G$6="All")+(SalesData[Salesperson]=$G$6))*(($H$6="All")+(SalesData[Product]=$H$6))*SalesData[Cost]) -> 238605.45 | F43: =SUMPRODUCT((SalesData[MonthNum]=$A$43)*(($B$6="All")+(SalesData[Year]=$B$6))*(($C$6="All")+(SalesData[Quarter]=$C$6))*(($E$6="All")+(SalesData[Region]=$E$6))*(($F$6="All")+(SalesData[Category]=$F$6))*(($G$6="All")+(SalesData[Salesperson]=$G$6))*(($H$6="All")+(SalesData[Product]=$H$6))*SalesData[Profit]) -> 146242.04 | G43: =IFERROR(B43/SUM($B$42:$B$53),0) -> 0.078313414 | H43: =IF(NOT(ISNUMBER($B$6)),"n/a",IF($B$6<=2022,"n/a",IFERROR((B43-SUMPRODUCT((SalesData[MonthNum]=$A$43)*(SalesData[Year]=$B$6-1)*(($C$6="All")+(SalesData[Quarter]=$C$6))*(($D$6="All")+(SalesData[Month]=$D$6))*(($E$6="All")+(SalesData[Region]=$E$6))*(($F$6="All")+(SalesData[Category]=$F$6))*(($G$6="All")+(SalesData[Salesperson]=$G$6))*(($H$6="All")+(SalesData[Product]=$H$6))*SalesData[Revenue]))/SUMPRODUCT((SalesData[MonthNum]=$A$43)*(SalesData[Year]=$B$6-1)*(($C$6="All")+(SalesData[Quarter]=$C$6))*(($D$6="All")+(SalesData[Month]=$D$6))*(($E$6="All")+(SalesData[Region]=$E$6))*(($F$6="All")+(SalesData[Category]=$F$6))*(($G$6="All")+(SalesData[Salesperson]=$G$6))*(($H$6="All")+(SalesData[Product]=$H$6))*SalesData[Revenue]),"n/a"))) -> 5.3928707 | I43: =B43*Dashboard!$AB$2 -> 384847.49 | J43: =F43*Dashboard!$AB$2 -> 146242.04
A44: 3 | B44: =SUMPRODUCT((SalesData[MonthNum]=$A$44)*(($B$6="All")+(SalesData[Year]=$B$6))*(($C$6="All")+(SalesData[Quarter]=$C$6))*(($E$6="All")+(SalesData[Region]=$E$6))*(($F$6="All")+(SalesData[Category]=$F$6))*(($G$6="All")+(SalesData[Salesperson]=$G$6))*(($H$6="All")+(SalesData[Product]=$H$6))*SalesData[Revenue]) -> 75262.54 | C44: =SUMPRODUCT((SalesData[MonthNum]=$A$44)*(($B$6="All")+(SalesData[Year]=$B$6))*(($C$6="All")+(SalesData[Quarter]=$C$6))*(($E$6="All")+(SalesData[Region]=$E$6))*(($F$6="All")+(SalesData[Category]=$F$6))*(($G$6="All")+(SalesData[Salesperson]=$G$6))*(($H$6="All")+(SalesData[Product]=$H$6))*((SalesData[Units]<>0))) -> 15 | D44: =SUMPRODUCT((SalesData[MonthNum]=$A$44)*(($B$6="All")+(SalesData[Year]=$B$6))*(($C$6="All")+(SalesData[Quarter]=$C$6))*(($E$6="All")+(SalesData[Region]=$E$6))*(($F$6="All")+(SalesData[Category]=$F$6))*(($G$6="All")+(SalesData[Salesperson]=$G$6))*(($H$6="All")+(SalesData[Product]=$H$6))*SalesData[Units]) -> 206 | E44: =SUMPRODUCT((SalesData[MonthNum]=$A$44)*(($B$6="All")+(SalesData[Year]=$B$6))*(($C$6="All")+(SalesData[Quarter]=$C$6))*(($E$6="All")+(SalesData[Region]=$E$6))*(($F$6="All")+(SalesData[Category]=$F$6))*(($G$6="All")+(SalesData[Salesperson]=$G$6))*(($H$6="All")+(SalesData[Product]=$H$6))*SalesData[Cost]) -> 46662.78 | F44: =SUMPRODUCT((SalesData[MonthNum]=$A$44)*(($B$6="All")+(SalesData[Year]=$B$6))*(($C$6="All")+(SalesData[Quarter]=$C$6))*(($E$6="All")+(SalesData[Region]=$E$6))*(($F$6="All")+(SalesData[Category]=$F$6))*(($G$6="All")+(SalesData[Salesperson]=$G$6))*(($H$6="All")+(SalesData[Product]=$H$6))*SalesData[Profit]) -> 28599.76 | G44: =IFERROR(B44/SUM($B$42:$B$53),0) -> 0.01531533 | H44: =IF(NOT(ISNUMBER($B$6)),"n/a",IF($B$6<=2022,"n/a",IFERROR((B44-SUMPRODUCT((SalesData[MonthNum]=$A$44)*(SalesData[Year]=$B$6-1)*(($C$6="All")+(SalesData[Quarter]=$C$6))*(($D$6="All")+(SalesData[Month]=$D$6))*(($E$6="All")+(SalesData[Region]=$E$6))*(($F$6="All")+(SalesData[Category]=$F$6))*(($G$6="All")+(SalesData[Salesperson]=$G$6))*(($H$6="All")+(SalesData[Product]=$H$6))*SalesData[Revenue]))/SUMPRODUCT((SalesData[MonthNum]=$A$44)*(SalesData[Year]=$B$6-1)*(($C$6="All")+(SalesData[Quarter]=$C$6))*(($D$6="All")+(SalesData[Month]=$D$6))*(($E$6="All")+(SalesData[Region]=$E$6))*(($F$6="All")+(SalesData[Category]=$F$6))*(($G$6="All")+(SalesData[Salesperson]=$G$6))*(($H$6="All")+(SalesData[Product]=$H$6))*SalesData[Revenue]),"n/a"))) -> 0.3987596 | I44: =B44*Dashboard!$AB$2 -> 75262.54 | J44: =F44*Dashboard!$AB$2 -> 28599.76
A45: 4 | B45: =SUMPRODUCT((SalesData[MonthNum]=$A$45)*(($B$6="All")+(SalesData[Year]=$B$6))*(($C$6="All")+(SalesData[Quarter]=$C$6))*(($E$6="All")+(SalesData[Region]=$E$6))*(($F$6="All")+(SalesData[Category]=$F$6))*(($G$6="All")+(SalesData[Salesperson]=$G$6))*(($H$6="All")+(SalesData[Product]=$H$6))*SalesData[Revenue]) -> 431756.67 | C45: =SUMPRODUCT((SalesData[MonthNum]=$A$45)*(($B$6="All")+(SalesData[Year]=$B$6))*(($C$6="All")+(SalesData[Quarter]=$C$6))*(($E$6="All")+(SalesData[Region]=$E$6))*(($F$6="All")+(SalesData[Category]=$F$6))*(($G$6="All")+(SalesData[Salesperson]=$G$6))*(($H$6="All")+(SalesData[Product]=$H$6))*((SalesData[Units]<>0))) -> 15 | D45: =SUMPRODUCT((SalesData[MonthNum]=$A$45)*(($B$6="All")+(SalesData[Year]=$B$6))*(($C$6="All")+(SalesData[Quarter]=$C$6))*(($E$6="All")+(SalesData[Region]=$E$6))*(($F$6="All")+(SalesData[Category]=$F$6))*(($G$6="All")+(SalesData[Salesperson]=$G$6))*(($H$6="All")+(SalesData[Product]=$H$6))*SalesData[Units]) -> 262 | E45: =SUMPRODUCT((SalesData[MonthNum]=$A$45)*(($B$6="All")+(SalesData[Year]=$B$6))*(($C$6="All")+(SalesData[Quarter]=$C$6))*(($E$6="All")+(SalesData[Region]=$E$6))*(($F$6="All")+(SalesData[Category]=$F$6))*(($G$6="All")+(SalesData[Salesperson]=$G$6))*(($H$6="All")+(SalesData[Product]=$H$6))*SalesData[Cost]) -> 267689.12 | F45: =SUMPRODUCT((SalesData[MonthNum]=$A$45)*(($B$6="All")+(SalesData[Year]=$B$6))*(($C$6="All")+(SalesData[Quarter]=$C$6))*(($E$6="All")+(SalesData[Region]=$E$6))*(($F$6="All")+(SalesData[Category]=$F$6))*(($G$6="All")+(SalesData[Salesperson]=$G$6))*(($H$6="All")+(SalesData[Product]=$H$6))*SalesData[Profit]) -> 164067.55 | G45: =IFERROR(B45/SUM($B$42:$B$53),0) -> 0.08785906 | H45: =IF(NOT(ISNUMBER($B$6)),"n/a",IF($B$6<=2022,"n/a",IFERROR((B45-SUMPRODUCT((SalesData[MonthNum]=$A$45)*(SalesData[Year]=$B$6-1)*(($C$6="All")+(SalesData[Quarter]=$C$6))*(($D$6="All")+(SalesData[Month]=$D$6))*(($E$6="All")+(SalesData[Region]=$E$6))*(($F$6="All")+(SalesData[Category]=$F$6))*(($G$6="All")+(SalesData[Salesperson]=$G$6))*(($H$6="All")+(SalesData[Product]=$H$6))*SalesData[Revenue]))/SUMPRODUCT((SalesData[MonthNum]=$A$45)*(SalesData[Year]=$B$6-1)*(($C$6="All")+(SalesData[Quarter]=$C$6))*(($D$6="All")+(SalesData[Month]=$D$6))*(($E$6="All")+(SalesData[Region]=$E$6))*(($F$6="All")+(SalesData[Category]=$F$6))*(($G$6="All")+(SalesData[Salesperson]=$G$6))*(($H$6="All")+(SalesData[Product]=$H$6))*SalesData[Revenue]),"n/a"))) -> -0.11975082 | I45: =B45*Dashboard!$AB$2 -> 431756.67 | J45: =F45*Dashboard!$AB$2 -> 164067.55
...
